2024-04-23 20:13:14,840 ERROR Exception occurred for link: https://www.labirint.ru/books/702477/
Traceback (most recent call last):
  File "C:\Users\Никита\AppData\Local\Temp\ipykernel_8428\857958171.py", line 32, in <module>
    descr = descr[0].text_content()
IndexError: list index out of range
2024-04-23 20:20:11,120 ERROR Exception occurred for link: https://www.labirint.ru/books/923643/
Traceback (most recent call last):
  File "C:\Users\Никита\AppData\Local\Temp\ipykernel_8428\857958171.py", line 44, in <module>
    pic_url = tree.xpath("//div[@id='product-image']/img")[0].get("data-src")
IndexError: list index out of range
2024-04-23 20:20:17,610 ERROR Exception occurred for link: https://www.labirint.ru/books/923642/
Traceback (most recent call last):
  File "C:\Users\Никита\AppData\Local\Temp\ipykernel_8428\857958171.py", line 44, in <module>
    pic_url = tree.xpath("//div[@id='product-image']/img")[0].get("data-src")
IndexError: list index out of range
2024-04-23 20:21:00,439 ERROR Exception occurred for link: https://www.labirint.ru/books/1000979/
Traceback (most recent call last):
  File "C:\Users\Никита\AppData\Local\Temp\ipykernel_8428\857958171.py", line 44, in <module>
    pic_url = tree.xpath("//div[@id='product-image']/img")[0].get("data-src")
IndexError: list index out of range
2024-04-23 20:22:25,608 ERROR Exception occurred for link: https://www.labirint.ru/books/933209/
Traceback (most recent call last):
  File "C:\Users\Никита\AppData\Local\Temp\ipykernel_8428\857958171.py", line 44, in <module>
    pic_url = tree.xpath("//div[@id='product-image']/img")[0].get("data-src")
IndexError: list index out of range
2024-04-23 20:22:39,193 ERROR Exception occurred for link: https://www.labirint.ru/books/753731/
Traceback (most recent call last):
  File "C:\Users\Никита\AppData\Local\Temp\ipykernel_8428\857958171.py", line 44, in <module>
    pic_url = tree.xpath("//div[@id='product-image']/img")[0].get("data-src")
IndexError: list index out of range
2024-04-23 20:22:40,341 ERROR Exception occurred for link: https://www.labirint.ru/books/933208/
Traceback (most recent call last):
  File "C:\Users\Никита\AppData\Local\Temp\ipykernel_8428\857958171.py", line 44, in <module>
    pic_url = tree.xpath("//div[@id='product-image']/img")[0].get("data-src")
IndexError: list index out of range
2024-04-23 20:22:46,697 ERROR Exception occurred for link: https://www.labirint.ru/books/937228/
Traceback (most recent call last):
  File "C:\Users\Никита\AppData\Local\Temp\ipykernel_8428\857958171.py", line 44, in <module>
    pic_url = tree.xpath("//div[@id='product-image']/img")[0].get("data-src")
IndexError: list index out of range
2024-04-23 20:23:49,899 ERROR Exception occurred for link: https://www.labirint.ru/books/937788/
Traceback (most recent call last):
  File "C:\Users\Никита\AppData\Local\Temp\ipykernel_8428\857958171.py", line 44, in <module>
    pic_url = tree.xpath("//div[@id='product-image']/img")[0].get("data-src")
IndexError: list index out of range
2024-04-23 20:25:12,718 ERROR Exception occurred for link: https://www.labirint.ru/books/859293/
Traceback (most recent call last):
  File "C:\Users\Никита\AppData\Local\Temp\ipykernel_8428\857958171.py", line 44, in <module>
    pic_url = tree.xpath("//div[@id='product-image']/img")[0].get("data-src")
IndexError: list index out of range
2024-04-23 20:26:58,346 ERROR Exception occurred for link: https://www.labirint.ru/books/455885/
Traceback (most recent call last):
  File "C:\Users\Никита\AppData\Local\Temp\ipykernel_8428\857958171.py", line 44, in <module>
    pic_url = tree.xpath("//div[@id='product-image']/img")[0].get("data-src")
IndexError: list index out of range
2024-04-23 20:27:01,265 ERROR Exception occurred for link: https://www.labirint.ru/books/455884/
Traceback (most recent call last):
  File "C:\Users\Никита\AppData\Local\Temp\ipykernel_8428\857958171.py", line 44, in <module>
    pic_url = tree.xpath("//div[@id='product-image']/img")[0].get("data-src")
IndexError: list index out of range
2024-04-23 20:27:18,325 ERROR Exception occurred for link: https://www.labirint.ru/books/484479/
Traceback (most recent call last):
  File "C:\Users\Никита\AppData\Local\Temp\ipykernel_8428\857958171.py", line 32, in <module>
    descr = descr[0].text_content()
IndexError: list index out of range
2024-04-23 20:27:27,224 ERROR Exception occurred for link: https://www.labirint.ru/books/851206/
Traceback (most recent call last):
  File "C:\Users\Никита\AppData\Local\Temp\ipykernel_8428\857958171.py", line 44, in <module>
    pic_url = tree.xpath("//div[@id='product-image']/img")[0].get("data-src")
IndexError: list index out of range
2024-04-23 20:29:28,958 ERROR Exception occurred for link: https://www.labirint.ru/books/446220/
Traceback (most recent call last):
  File "C:\Users\Никита\AppData\Local\Temp\ipykernel_8428\857958171.py", line 32, in <module>
    descr = descr[0].text_content()
IndexError: list index out of range
2024-04-23 20:29:40,195 ERROR Exception occurred for link: https://www.labirint.ru/books/517036/
Traceback (most recent call last):
  File "C:\Users\Никита\AppData\Local\Temp\ipykernel_8428\857958171.py", line 44, in <module>
    pic_url = tree.xpath("//div[@id='product-image']/img")[0].get("data-src")
IndexError: list index out of range
2024-04-23 20:32:04,419 ERROR Exception occurred for link: https://www.labirint.ru/books/366331/
Traceback (most recent call last):
  File "C:\Users\Никита\AppData\Local\Temp\ipykernel_8428\857958171.py", line 32, in <module>
    descr = descr[0].text_content()
IndexError: list index out of range
2024-04-23 20:33:38,059 ERROR Exception occurred for link: https://www.labirint.ru/books/517048/
Traceback (most recent call last):
  File "C:\Users\Никита\AppData\Local\Temp\ipykernel_8428\857958171.py", line 44, in <module>
    pic_url = tree.xpath("//div[@id='product-image']/img")[0].get("data-src")
IndexError: list index out of range
2024-04-23 20:34:17,898 ERROR Exception occurred for link: https://www.labirint.ru/books/495/
Traceback (most recent call last):
  File "C:\Users\Никита\AppData\Local\Temp\ipykernel_8428\857958171.py", line 32, in <module>
    descr = descr[0].text_content()
IndexError: list index out of range
