2024-04-17 20:28:54,832 ERROR Exception occurred for link: https://www.labirint.ru/books/817306/
Traceback (most recent call last):
  File "C:\Users\Никита\AppData\Local\Temp\ipykernel_11400\3747864753.py", line 32, in <module>
    descr = descr[0].text_content()
IndexError: list index out of range
2024-04-17 20:29:37,694 ERROR Exception occurred for link: https://www.labirint.ru/books/897902/
Traceback (most recent call last):
  File "C:\Users\Никита\AppData\Local\Temp\ipykernel_11400\3747864753.py", line 32, in <module>
    descr = descr[0].text_content()
IndexError: list index out of range
2024-04-17 20:29:47,722 ERROR Exception occurred for link: https://www.labirint.ru/books/892549/
Traceback (most recent call last):
  File "C:\Users\Никита\AppData\Local\Temp\ipykernel_11400\3747864753.py", line 32, in <module>
    descr = descr[0].text_content()
IndexError: list index out of range
2024-04-17 20:29:49,922 ERROR Exception occurred for link: https://www.labirint.ru/books/891970/
Traceback (most recent call last):
  File "C:\Users\Никита\AppData\Local\Temp\ipykernel_11400\3747864753.py", line 32, in <module>
    descr = descr[0].text_content()
IndexError: list index out of range
2024-04-17 20:29:59,596 ERROR Exception occurred for link: https://www.labirint.ru/books/903329/
Traceback (most recent call last):
  File "C:\Users\Никита\AppData\Local\Temp\ipykernel_11400\3747864753.py", line 32, in <module>
    descr = descr[0].text_content()
IndexError: list index out of range
2024-04-17 20:30:00,759 ERROR Exception occurred for link: https://www.labirint.ru/books/902413/
Traceback (most recent call last):
  File "C:\Users\Никита\AppData\Local\Temp\ipykernel_11400\3747864753.py", line 32, in <module>
    descr = descr[0].text_content()
IndexError: list index out of range
2024-04-17 20:30:15,800 ERROR Exception occurred for link: https://www.labirint.ru/books/903401/
Traceback (most recent call last):
  File "C:\Users\Никита\AppData\Local\Temp\ipykernel_11400\3747864753.py", line 32, in <module>
    descr = descr[0].text_content()
IndexError: list index out of range
2024-04-17 20:30:32,766 ERROR Exception occurred for link: https://www.labirint.ru/books/881238/
Traceback (most recent call last):
  File "C:\Users\Никита\AppData\Local\Temp\ipykernel_11400\3747864753.py", line 32, in <module>
    descr = descr[0].text_content()
IndexError: list index out of range
2024-04-17 20:30:46,030 ERROR Exception occurred for link: https://www.labirint.ru/books/903340/
Traceback (most recent call last):
  File "C:\Users\Никита\AppData\Local\Temp\ipykernel_11400\3747864753.py", line 32, in <module>
    descr = descr[0].text_content()
IndexError: list index out of range
2024-04-17 20:31:06,932 ERROR Exception occurred for link: https://www.labirint.ru/books/896731/
Traceback (most recent call last):
  File "C:\Users\Никита\AppData\Local\Temp\ipykernel_11400\3747864753.py", line 32, in <module>
    descr = descr[0].text_content()
IndexError: list index out of range
2024-04-17 20:31:18,639 ERROR Exception occurred for link: https://www.labirint.ru/books/898060/
Traceback (most recent call last):
  File "C:\Users\Никита\AppData\Local\Temp\ipykernel_11400\3747864753.py", line 32, in <module>
    descr = descr[0].text_content()
IndexError: list index out of range
2024-04-17 20:32:02,765 ERROR Exception occurred for link: https://www.labirint.ru/books/857310/
Traceback (most recent call last):
  File "C:\Users\Никита\AppData\Local\Temp\ipykernel_11400\3747864753.py", line 32, in <module>
    descr = descr[0].text_content()
IndexError: list index out of range
2024-04-17 20:32:46,253 ERROR Exception occurred for link: https://www.labirint.ru/books/716279/
Traceback (most recent call last):
  File "C:\Users\Никита\AppData\Local\Temp\ipykernel_11400\3747864753.py", line 32, in <module>
    descr = descr[0].text_content()
IndexError: list index out of range
2024-04-17 20:33:07,093 ERROR Exception occurred for link: https://www.labirint.ru/books/898638/
Traceback (most recent call last):
  File "C:\Users\Никита\AppData\Local\Temp\ipykernel_11400\3747864753.py", line 32, in <module>
    descr = descr[0].text_content()
IndexError: list index out of range
2024-04-17 20:37:03,688 ERROR Exception occurred for link: https://www.labirint.ru/books/768179/
Traceback (most recent call last):
  File "C:\Users\Никита\AppData\Local\Temp\ipykernel_11400\3747864753.py", line 32, in <module>
    descr = descr[0].text_content()
IndexError: list index out of range
2024-04-17 20:41:24,090 ERROR Exception occurred for link: https://www.labirint.ru/books/783682/
Traceback (most recent call last):
  File "C:\Users\Никита\AppData\Local\Temp\ipykernel_11400\2213925547.py", line 44, in <module>
    pic_url = tree.xpath("//div[@id='product-image']/img")[0].get("data-src")
IndexError: list index out of range
2024-04-17 20:41:55,803 ERROR Exception occurred for link: https://www.labirint.ru/books/969979/
Traceback (most recent call last):
  File "C:\Users\Никита\AppData\Local\Temp\ipykernel_11400\2213925547.py", line 32, in <module>
    descr = descr[0].text_content()
IndexError: list index out of range
